Workbook

Sheet Instructions
B2: Emagine U At Play — UAT Checklist
B3: End-to-end User Acceptance Testing checklist for the daycare + therapy management system
B5: How to use this workbook
B6: 1. Open the "UAT Checklist" tab. It lists every test case across all 22 modules, in build order.
B7: 2. Work through it top to bottom, or use the filter arrows on row 1 to test one module at a time.
B8: 3. For each row: perform the Steps to Execute, compare the real result to Expected Result, then fill in Status, Actual Result / Comments, Tested By, and Date Tested.
B9: 4. Only edit the columns Status, Actual Result / Comments, Tested By, and Date Tested — every other column is the test spec itself and shouldn't be changed.
B10: 5. Check the "Summary" tab any time for a live pass/fail count per module — it updates automatically from your Status entries.
B12: Status column legend
B13: Not Tested — default state, not yet attempted
B14: Pass — behaved exactly as Expected Result describes
B15: Fail — did not match Expected Result — describe what happened in Actual Result / Comments
... B26: Have at least one seeded parent account with a child, and one seeded staff account, so role-based test cases (marked across every module) have something real to check against.

Sheet Summary
B2: UAT Progress Summary
B3: Updates automatically from the Status column on the UAT Checklist tab
B5: Module | C5: Total Cases | D5: Not Tested | E5: Pass | F5: Fail | G5: Blocked | H5: N/A | I5: Pass Rate
B6: Authentication | C6: =COUNTIF('UAT Checklist'!$B$2:$B$127,$B6) | D6: =COUNTIFS('UAT Checklist'!$B$2:$B$127,$B6,'UAT Checklist'!$H$2:$H$127,"Not Tested") | E6: =COUNTIFS('UAT Checklist'!$B$2:$B$127,$B6,'UAT Checklist'!$H$2:$H$127,"Pass") | F6: =COUNTIFS('UAT Checklist'!$B$2:$B$127,$B6,'UAT Checklist'!$H$2:$H$127,"Fail") | G6: =COUNTIFS('UAT Checklist'!$B$2:$B$127,$B6,'UAT Checklist'!$H$2:$H$127,"Blocked") | H6: =COUNTIFS('UAT Checklist'!$B$2:$B$127,$B6,'UAT Checklist'!$H$2:$H$127,"N/A") | I6: =IFERROR(E6/C6,0)
B7: User Management | C7: =COUNTIF('UAT Checklist'!$B$2:$B$127,$B7) | D7: =COUNTIFS('UAT Checklist'!$B$2:$B$127,$B7,'UAT Checklist'!$H$2:$H$127,"Not Tested") | E7: =COUNTIFS('UAT Checklist'!$B$2:$B$127,$B7,'UAT Checklist'!$H$2:$H$127,"Pass") | F7: =COUNTIFS('UAT Checklist'!$B$2:$B$127,$B7,'UAT Checklist'!$H$2:$H$127,"Fail") | G7: =COUNTIFS('UAT Checklist'!$B$2:$B$127,$B7,'UAT Checklist'!$H$2:$H$127,"Blocked") | H7: =COUNTIFS('UAT Checklist'!$B$2:$B$127,$B7,'UAT Checklist'!$H$2:$H$127,"N/A") | I7: =IFERROR(E7/C7,0)
B8: Roles & Permissions | C8: =COUNTIF('UAT Checklist'!$B$2:$B$127,$B8) | D8: =COUNTIFS('UAT Checklist'!$B$2:$B$127,$B8,'UAT Checklist'!$H$2:$H$127,"Not Tested") | E8: =COUNTIFS('UAT Checklist'!$B$2:$B$127,$B8,'UAT Checklist'!$H$2:$H$127,"Pass") | F8: =COUNTIFS('UAT Checklist'!$B$2:$B$127,$B8,'UAT Checklist'!$H$2:$H$127,"Fail") | G8: =COUNTIFS('UAT Checklist'!$B$2:$B$127,$B8,'UAT Checklist'!$H$2:$H$127,"Blocked") | H8: =COUNTIFS('UAT Checklist'!$B$2:$B$127,$B8,'UAT Checklist'!$H$2:$H$127,"N/A") | I8: =IFERROR(E8/C8,0)
B9: Children Management | C9: =COUNTIF('UAT Checklist'!$B$2:$B$127,$B9) | D9: =COUNTIFS('UAT Checklist'!$B$2:$B$127,$B9,'UAT Checklist'!$H$2:$H$127,"Not Tested") | E9: =COUNTIFS('UAT Checklist'!$B$2:$B$127,$B9,'UAT Checklist'!$H$2:$H$127,"Pass") | F9: =COUNTIFS('UAT Checklist'!$B$2:$B$127,$B9,'UAT Checklist'!$H$2:$H$127,"Fail") | G9: =COUNTIFS('UAT Checklist'!$B$2:$B$127,$B9,'UAT Checklist'!$H$2:$H$127,"Blocked") | H9: =COUNTIFS('UAT Checklist'!$B$2:$B$127,$B9,'UAT Checklist'!$H$2:$H$127,"N/A") | I9: =IFERROR(E9/C9,0)
B10: Guardian-Child Access | C10: =COUNTIF('UAT Checklist'!$B$2:$B$127,$B10) | D10: =COUNTIFS('UAT Checklist'!$B$2:$B$127,$B10,'UAT Checklist'!$H$2:$H$127,"Not Tested") | E10: =COUNTIFS('UAT Checklist'!$B$2:$B$127,$B10,'UAT Checklist'!$H$2:$H$127,"Pass") | F10: =COUNTIFS('UAT Checklist'!$B$2:$B$127,$B10,'UAT Checklist'!$H$2:$H$127,"Fail") | G10: =COUNTIFS('UAT Checklist'!$B$2:$B$127,$B10,'UAT Checklist'!$H$2:$H$127,"Blocked") | H10: =COUNTIFS('UAT Checklist'!$B$2:$B$127,$B10,'UAT Checklist'!$H$2:$H$127,"N/A") | I10: =IFERROR(E10/C10,0)
B11: Programs | C11: =COUNTIF('UAT Checklist'!$B$2:$B$127,$B11) | D11: =COUNTIFS('UAT Checklist'!$B$2:$B$127,$B11,'UAT Checklist'!$H$2:$H$127,"Not Tested") | E11: =COUNTIFS('UAT Checklist'!$B$2:$B$127,$B11,'UAT Checklist'!$H$2:$H$127,"Pass") | F11: =COUNTIFS('UAT Checklist'!$B$2:$B$127,$B11,'UAT Checklist'!$H$2:$H$127,"Fail") | G11: =COUNTIFS('UAT Checklist'!$B$2:$B$127,$B11,'UAT Checklist'!$H$2:$H$127,"Blocked") | H11: =COUNTIFS('UAT Checklist'!$B$2:$B$127,$B11,'UAT Checklist'!$H$2:$H$127,"N/A") | I11: =IFERROR(E11/C11,0)
B12: Enrollments | C12: =COUNTIF('UAT Checklist'!$B$2:$B$127,$B12) | D12: =COUNTIFS('UAT Checklist'!$B$2:$B$127,$B12,'UAT Checklist'!$H$2:$H$127,"Not Tested") | E12: =COUNTIFS('UAT Checklist'!$B$2:$B$127,$B12,'UAT Checklist'!$H$2:$H$127,"Pass") | F12: =COUNTIFS('UAT Checklist'!$B$2:$B$127,$B12,'UAT Checklist'!$H$2:$H$127,"Fail") | G12: =COUNTIFS('UAT Checklist'!$B$2:$B$127,$B12,'UAT Checklist'!$H$2:$H$127,"Blocked") | H12: =COUNTIFS('UAT Checklist'!$B$2:$B$127,$B12,'UAT Checklist'!$H$2:$H$127,"N/A") | I12: =IFERROR(E12/C12,0)
B13: Waitlist | C13: =COUNTIF('UAT Checklist'!$B$2:$B$127,$B13) | D13: =COUNTIFS('UAT Checklist'!$B$2:$B$127,$B13,'UAT Checklist'!$H$2:$H$127,"Not Tested") | E13: =COUNTIFS('UAT Checklist'!$B$2:$B$127,$B13,'UAT Checklist'!$H$2:$H$127,"Pass") | F13: =COUNTIFS('UAT Checklist'!$B$2:$B$127,$B13,'UAT Checklist'!$H$2:$H$127,"Fail") | G13: =COUNTIFS('UAT Checklist'!$B$2:$B$127,$B13,'UAT Checklist'!$H$2:$H$127,"Blocked") | H13: =COUNTIFS('UAT Checklist'!$B$2:$B$127,$B13,'UAT Checklist'!$H$2:$H$127,"N/A") | I13: =IFERROR(E13/C13,0)
B14: Attendance | C14: =COUNTIF('UAT Checklist'!$B$2:$B$127,$B14) | D14: =COUNTIFS('UAT Checklist'!$B$2:$B$127,$B14,'UAT Checklist'!$H$2:$H$127,"Not Tested") | E14: =COUNTIFS('UAT Checklist'!$B$2:$B$127,$B14,'UAT Checklist'!$H$2:$H$127,"Pass") | F14: =COUNTIFS('UAT Checklist'!$B$2:$B$127,$B14,'UAT Checklist'!$H$2:$H$127,"Fail") | G14: =COUNTIFS('UAT Checklist'!$B$2:$B$127,$B14,'UAT Checklist'!$H$2:$H$127,"Blocked") | H14: =COUNTIFS('UAT Checklist'!$B$2:$B$127,$B14,'UAT Checklist'!$H$2:$H$127,"N/A") | I14: =IFERROR(E14/C14,0)
B15: Child Daily Logs | C15: =COUNTIF('UAT Checklist'!$B$2:$B$127,$B15) | D15: =COUNTIFS('UAT Checklist'!$B$2:$B$127,$B15,'UAT Checklist'!$H$2:$H$127,"Not Tested") | E15: =COUNTIFS('UAT Checklist'!$B$2:$B$127,$B15,'UAT Checklist'!$H$2:$H$127,"Pass") | F15: =COUNTIFS('UAT Checklist'!$B$2:$B$127,$B15,'UAT Checklist'!$H$2:$H$127,"Fail") | G15: =COUNTIFS('UAT Checklist'!$B$2:$B$127,$B15,'UAT Checklist'!$H$2:$H$127,"Blocked") | H15: =COUNTIFS('UAT Checklist'!$B$2:$B$127,$B15,'UAT Checklist'!$H$2:$H$127,"N/A") | I15: =IFERROR(E15/C15,0)
B16: Documents | C16: =COUNTIF('UAT Checklist'!$B$2:$B$127,$B16) | D16: =COUNTIFS('UAT Checklist'!$B$2:$B$127,$B16,'UAT Checklist'!$H$2:$H$127,"Not Tested") | E16: =COUNTIFS('UAT Checklist'!$B$2:$B$127,$B16,'UAT Checklist'!$H$2:$H$127,"Pass") | F16: =COUNTIFS('UAT Checklist'!$B$2:$B$127,$B16,'UAT Checklist'!$H$2:$H$127,"Fail") | G16: =COUNTIFS('UAT Checklist'!$B$2:$B$127,$B16,'UAT Checklist'!$H$2:$H$127,"Blocked") | H16: =COUNTIFS('UAT Checklist'!$B$2:$B$127,$B16,'UAT Checklist'!$H$2:$H$127,"N/A") | I16: =IFERROR(E16/C16,0)
B17: Activities | C17: =COUNTIF('UAT Checklist'!$B$2:$B$127,$B17) | D17: =COUNTIFS('UAT Checklist'!$B$2:$B$127,$B17,'UAT Checklist'!$H$2:$H$127,"Not Tested") | E17: =COUNTIFS('UAT Checklist'!$B$2:$B$127,$B17,'UAT Checklist'!$H$2:$H$127,"Pass") | F17: =COUNTIFS('UAT Checklist'!$B$2:$B$127,$B17,'UAT Checklist'!$H$2:$H$127,"Fail") | G17: =COUNTIFS('UAT Checklist'!$B$2:$B$127,$B17,'UAT Checklist'!$H$2:$H$127,"Blocked") | H17: =COUNTIFS('UAT Checklist'!$B$2:$B$127,$B17,'UAT Checklist'!$H$2:$H$127,"N/A") | I17: =IFERROR(E17/C17,0)
... B27: Security & Non-Functional | C27: =COUNTIF('UAT Checklist'!$B$2:$B$127,$B27) | D27: =COUNTIFS('UAT Checklist'!$B$2:$B$127,$B27,'UAT Checklist'!$H$2:$H$127,"Not Tested") | E27: =COUNTIFS('UAT Checklist'!$B$2:$B$127,$B27,'UAT Checklist'!$H$2:$H$127,"Pass") | F27: =COUNTIFS('UAT Checklist'!$B$2:$B$127,$B27,'UAT Checklist'!$H$2:$H$127,"Fail") | G27: =COUNTIFS('UAT Checklist'!$B$2:$B$127,$B27,'UAT Checklist'!$H$2:$H$127,"Blocked") | H27: =COUNTIFS('UAT Checklist'!$B$2:$B$127,$B27,'UAT Checklist'!$H$2:$H$127,"N/A") | I27: =IFERROR(E27/C27,0)
B28: TOTAL | C28: =SUM(C6:C27) | D28: =SUM(D6:D27) | E28: =SUM(E6:E27) | F28: =SUM(F6:F27) | G28: =SUM(G6:G27) | H28: =SUM(H6:H27) | I28: =IFERROR(E28/C28,0)

Sheet UAT Checklist
A1: # | B1: Module | C1: Test ID | D1: Test Scenario | E1: Steps to Execute | F1: Expected Result | G1: Priority | H1: Status | I1: Actual Result / Comments | J1: Tested By | K1: Date Tested
A2: 1 | B2: Authentication | C2: AUTH-01 | D2: Parent self-registration | E2: 1. Go to /register 2. Select role = Parent 3. Fill first/last name, email, phone, password 4. Submit | F2: New user created with role=parent; matching parents profile row created; user auto-logged in and redirected to dashboard | G2: High | H2: Pass
A3: 2 | B3: Authentication | C3: AUTH-02 | D3: Staff self-registration | E3: 1. Go to /register 2. Select role = Staff 3. Fill required fields 4. Submit | F3: staff profile row created with default role=teacher; redirected to dashboard | G3: High | H3: Pass
A4: 3 | B4: Authentication | C4: AUTH-03 | D4: Duplicate email registration | E4: 1. Register using an email already in the users table | F4: Validation error shown: email already taken; no duplicate row created | G4: Medium | H4: Pass
A5: 4 | B5: Authentication | C5: AUTH-04 | D5: Successful login | E5: 1. Go to /login 2. Enter correct email/password 3. Submit | F5: Redirected to dashboard; last_login timestamp updated; session established | G5: High | H5: Pass
A6: 5 | B6: Authentication | C6: AUTH-05 | D6: Login with wrong password | E6: 1. Enter correct email, incorrect password 2. Submit | F6: Error "credentials do not match" shown; rate limiter attempt count increases | G6: High | H6: Pass
A7: 6 | B7: Authentication | C7: AUTH-06 | D7: Login lockout after repeated failures | E7: 1. Attempt login with wrong password 5 times within a minute 2. Try a 6th time | F7: Locked out with a "too many attempts, try again in X seconds" message | G7: High | H7: Pass
A8: 7 | B8: Authentication | C8: AUTH-07 | D8: Deactivated account login | E8: 1. Admin sets a user's is_active = false 2. That user attempts to log in with correct credentials | F8: Login is immediately reversed; "account deactivated" message shown; user is logged out | G8: High | H8: Pass
A9: 8 | B9: Authentication | C9: AUTH-08 | D9: Logout | E9: 1. While logged in, click Logout | F9: Session invalidated and token regenerated; redirected to /login | G9: Medium | H9: Pass
A10: 9 | B10: Authentication | C10: AUTH-09 | D10: Forgot password request | E10: 1. Go to /forgot-password 2. Submit a registered email | F10: Reset link emailed; success status message shown | G10: Medium | H10: Not Tested
A11: 10 | B11: Authentication | C11: AUTH-10 | D11: Reset password via emailed link | E11: 1. Open the emailed reset link 2. Enter and confirm a new password 3. Submit | F11: Password updated; can log in with new password; old password no longer works | G11: Medium | H11: Not Tested
A12: 11 | B12: User Management | C12: USER-01 | D12: Admin creates a parent account | E12: 1. Login as admin 2. Go to Create User 3. Select role=Parent, fill fields, submit | F12: User + parents profile row created together in one transaction; Spatie parent role assigned | G12: High | H12: Pass
A13: 12 | B13: User Management | C13: USER-02 | D13: Admin creates a staff account | E13: 1. Same as USER-01 with role=Staff | F13: User + staff profile row created; Spatie staff role assigned | G13: High | H13: Pass
... A20: 19 | B20: Roles & Permissions | C20: PERM-05 | D20: Revoking a permission updates the menu | E20: 1. Remove a permission from the staff role 2. Log out and back in as a staff user | F20: The corresponding sidebar item is no longer visible | G20: Low | H20: Pass
A21: 20 | B21: Children Management | C21: CHILD-01 | D21: Create a child links a guardian automatically | E21: 1. Admin/staff creates a new child under a parent | F21: A guardian_child row is auto-created linking the billing parent, accepted_at set, access_level=full | G21: High | H21: Pass | I21: User View Needed
A22: 21 | B22: Children Management | C22: CHILD-02 | D22: Parent sees only their own children | E22: 1. Login as a parent with 1+ children 2. Go to Children index | F22: Only that parent's linked children appear; no other family's children | G22: High | H22: Pass
A23: 22 | B23: Children Management | C23: CHILD-03 | D23: Parent blocked from another family's child | E23: 1. As a parent, note another family's child ID 2. Visit /children/{id} directly | F23: 403 Forbidden — ChildPolicy blocks it | G23: High | H23: Pass | I23: Child View Needed
A24: 23 | B24: Children Management | C24: CHILD-04 | D24: Staff sees all active children | E24: 1. Login as staff 2. Go to Children index | F24: All is_active=true children appear regardless of family | G24: Medium | H24: Pass
A25: 24 | B25: Children Management | C25: CHILD-05 | D25: Edit a child record | E25: 1. Admin/staff opens a child 2. Updates a field (e.g. allergies) 3. Saves | F25: Update persists and displays correctly on reload | G25: Medium | H25: Pass
A26: 25 | B26: Children Management | C26: CHILD-06 | D26: View-only guardian blocked from editing | E26: 1. A guardian with access_level=view_only attempts to edit the child | F26: Edit action is blocked by policy | G26: High | H26: Pass
A27: 26 | B27: Children Management | C27: CHILD-07 | D27: Deactivate a child (soft delete) | E27: 1. Admin deactivates a child | F27: is_active becomes false; attendance/billing history remains intact, not deleted | G27: High | H27: Pass
A28: 27 | B28: Children Management | C28: CHILD-08 | D28: Emergency contact fields save correctly | E28: 1. Fill ec_name, ec_relationship, ec_phone, ec_authorized_pickup 2. Save and reopen | F28: All four fields display exactly as entered | G28: Medium | H28: Pass
A29: 28 | B29: Guardian-Child Access | C29: GUARD-01 | D29: Pending guardian invite has no access yet | E29: 1. Add a second guardian to a child with accepted_at left null | F29: That guardian cannot see the child in their account yet | G29: High | H29: Not Tested
A30: 29 | B30: Guardian-Child Access | C30: GUARD-02 | D30: Accepted guardian gains access | E30: 1. Set accepted_at on that guardian_child row (simulating acceptance) | F30: The guardian can now view the child | G30: High | H30: Not Tested
A31: 30 | B31: Guardian-Child Access | C31: GUARD-03 | D31: can_pickup flag reflected correctly | E31: 1. Set can_pickup=false for a guardian 2. Check wherever pickup authorization is displayed | F31: Correctly shown as not authorized for pickup | G31: Medium | H31: Not Tested | I31: authorized for pickup - not showing
A32: 31 | B32: Guardian-Child Access | C32: GUARD-04 | D32: Primary guardian flag is accurate | E32: 1. Check is_primary on the auto-created guardian_child row from CHILD-01 | F32: The billing parent is marked is_primary=true | G32: Low | H32: Not Tested | I32: is_primary=true not marked in parent list
A33: 32 | B33: Programs | C33: PROG-01 | D33: Create a new program | E33: 1. Admin creates a program with name, age range, capacity, billing model | F33: Program saved and appears in the catalog | G33: Medium | H33: Pass
A34: 33 | B34: Programs | C34: PROG-02 | D34: State-funded program shows $0 fee | E34: 1. Create/view a program with billing_model=state_funded | F34: monthly_fee displays as $0 / not applicable | G34: Medium | H34: N/A
A35: 34 | B35: Programs | C35: PROG-03 | D35: Deactivated program hidden from enrollment | E35: 1. Set a program's is_active=false 2. Start a new enrollment | F35: That program no longer appears as a selectable option | G35: Medium | H35: Pass
A36: 35 | B36: Programs | C36: PROG-04 | D36: Drop-in program uses daily_rate | E36: 1. Create a program with service_type=drop_in | F36: daily_rate field is used/required; monthly_fee stays empty | G36: Medium | H36: Fail
A37: 36 | B37: Programs | C37: PROG-05 | D37: Non-admin blocked from managing programs | E37: 1. Login as staff or parent 2. Attempt to create/edit a program | F37: Access denied | G37: High | H37: Pass
A38: 37 | B38: Enrollments | C38: ENR-01 | D38: Enroll within age range succeeds | E38: 1. Enroll a child whose age fits the program's min/max_age_months | F38: Enrollment created with status=pending or active | G38: High | H38: Pass
A39: 38 | B39: Enrollments | C39: ENR-02 | D39: Enroll outside age range blocked | E39: 1. Attempt to enroll a child outside the program's age range | F39: Validation/business rule blocks it with a clear message | G39: High | H39: Pass | I39: It checks enrollment start date, not the child age on today - I think it is ok.
A40: 39 | B40: Enrollments | C40: ENR-03 | D40: Enrollment at full capacity goes to waitlist | E40: 1. Enroll into a program already at its capacity limit | F40: Child is routed to the waitlist instead of being enrolled | G40: High | H40: Pass | I40: It is not allowing to enroll which is right.
A41: 40 | B41: Enrollments | C41: ENR-04 | D41: Status progression | E41: 1. Move an enrollment from pending → approved → active | F41: Each transition saves correctly; approved_at/approved_by populate on approval | G41: Medium | H41: Pass | I41: Only Pending and Active status are there.
A42: 41 | B42: Enrollments | C42: ENR-05 | D42: Withdraw an active enrollment | E42: 1. Withdraw a currently active enrollment | F42: status becomes withdrawn; end_date is recorded | G42: Medium | H42: Pass
A43: 42 | B43: Enrollments | C43: ENR-06 | D43: enrolled_by is recorded | E43: 1. Submit a new enrollment as a specific admin/staff user | F43: enrolled_by correctly stores that user's ID | G43: Low | H43: Pass
A44: 43 | B44: Waitlist | C44: WAIT-01 | D44: Waitlist position assigned | E44: 1. Add a child to a full program's waitlist | F44: A position number is assigned (e.g. next available) | G44: Medium | H44: N/A | I44: Waitlist module not built in current code: waitlist table has only id/timestamps; no model, screens or routes. Full programs block enrollment (capacity check) instead.
A45: 44 | B45: Waitlist | C45: WAIT-02 | D45: Offer a waitlist slot | E45: 1. A spot opens; change status from waiting to offered | F45: Status updates correctly; child is notified per your process | G45: Medium | H45: N/A | I45: Waitlist module not built in current code: waitlist table has only id/timestamps; no model, screens or routes. Full programs block enrollment (capacity check) instead.
A46: 45 | B46: Waitlist | C46: WAIT-03 | D46: Expired offer | E46: 1. Let an offered waitlist entry pass its response window | F46: Status updates to expired | G46: Low | H46: N/A | I46: Waitlist module not built in current code: waitlist table has only id/timestamps; no model, screens or routes. Full programs block enrollment (capacity check) instead.
...
